ERROR    [2017-04-07 11:37:44,222] Failed.
Traceback (most recent call last):
  File "/home/alina/my_test_project/make_vocabulary.py", line 23, in read_file
    file = open(file_name, FILE_OPEN_MODE)
IOError: [Errno 21] Is a directory: '/home/alina/my_test_project/'
ERROR    [2017-04-07 11:37:47,875] Failed.
Traceback (most recent call last):
  File "/home/alina/my_test_project/make_vocabulary.py", line 13, in take_file_name
    file_name = sys.argv[1]
IndexError: list index out of range
ERROR    [2017-04-07 11:37:47,924] Failed.
Traceback (most recent call last):
  File "/home/alina/my_test_project/make_vocabulary.py", line 23, in read_file
    file = open(file_name, FILE_OPEN_MODE)
IOError: [Errno 21] Is a directory: '/home/alina/my_test_project/'
ERROR    [2017-04-07 11:37:47,970] Failed.
Traceback (most recent call last):
  File "/home/alina/my_test_project/make_vocabulary.py", line 23, in read_file
    file = open(file_name, FILE_OPEN_MODE)
IOError: [Errno 13] Permission denied: '/home/alina/my_test_project/sct/tests//test_negative/permission_denied_file.txt'
ERROR    [2017-04-07 11:40:05,746] Failed.
Traceback (most recent call last):
  File "/home/alina/my_test_project/make_vocabulary.py", line 13, in take_file_name
    file_name = sys.argv[1]
IndexError: list index out of range
ERROR    [2017-04-07 11:40:05,796] Failed.
Traceback (most recent call last):
  File "/home/alina/my_test_project/make_vocabulary.py", line 23, in read_file
    file = open(file_name, FILE_OPEN_MODE)
IOError: [Errno 21] Is a directory: '/home/alina/my_test_project/'
ERROR    [2017-04-07 11:40:05,839] Failed.
Traceback (most recent call last):
  File "/home/alina/my_test_project/make_vocabulary.py", line 23, in read_file
    file = open(file_name, FILE_OPEN_MODE)
IOError: [Errno 13] Permission denied: '/home/alina/my_test_project/sct/tests//test_negative/permission_denied_file.txt'
ERROR    [2017-04-07 13:22:16,423] Failed.
Traceback (most recent call last):
  File "/home/alina/my_test_project/make_vocabulary.py", line 24, in read_file
    file = open(file_name, FILE_OPEN_MODE)
IOError: [Errno 2] No such file or directory: 'fileNotExist'
ERROR    [2017-04-07 13:22:21,254] Failed.
Traceback (most recent call last):
  File "/home/alina/my_test_project/make_vocabulary.py", line 13, in take_file_name
    file_name = sys.argv[1]
IndexError: list index out of range
ERROR    [2017-04-07 13:22:21,317] Failed.
Traceback (most recent call last):
  File "/home/alina/my_test_project/make_vocabulary.py", line 24, in read_file
    file = open(file_name, FILE_OPEN_MODE)
IOError: [Errno 21] Is a directory: '/home/alina/my_test_project/'
ERROR    [2017-04-07 13:22:21,392] Failed.
Traceback (most recent call last):
  File "/home/alina/my_test_project/make_vocabulary.py", line 24, in read_file
    file = open(file_name, FILE_OPEN_MODE)
IOError: [Errno 13] Permission denied: '/home/alina/my_test_project/sct/tests//test_negative/permission_denied_file.txt'
ERROR    [2017-04-07 13:22:26,969] Failed.
Traceback (most recent call last):
  File "/home/alina/my_test_project/make_vocabulary.py", line 13, in take_file_name
    file_name = sys.argv[1]
IndexError: list index out of range
