ERROR    [2017-04-05 13:08:07,211] Failed.
Traceback (most recent call last):
  File "/home/alina/my_test_project/make_vocabulary.py", line 13, in take_file_name
    file_name = sys.argv[1]
IndexError: list index out of range
ERROR    [2017-04-05 14:28:15,835] Failed.
Traceback (most recent call last):
  File "/home/alina/my_test_project/make_vocabulary.py", line 18, in take_file_name
    file_name = sys.argv[1]
IndexError: list index out of range
ERROR    [2017-04-05 14:28:41,149] Failed.
Traceback (most recent call last):
  File "/home/alina/my_test_project/make_vocabulary.py", line 29, in read_file
    file = open(file_name, FileOpenMode)
IOError: [Errno 2] No such file or directory: 'fileNotExist'
ERROR    [2017-04-05 14:29:07,567] Failed.
Traceback (most recent call last):
  File "/home/alina/my_test_project/make_vocabulary.py", line 29, in read_file
    file = open(file_name, FileOpenMode)
IOError: [Errno 2] No such file or directory: 'fileNotExist'
ERROR    [2017-04-06 09:43:36,415] Failed.
Traceback (most recent call last):
  File "/home/alina/my_test_project/make_vocabulary.py", line 16, in take_file_name
    file_name = sys.argv[1]
IndexError: list index out of range
ERROR    [2017-04-06 10:47:07,477] Failed.
Traceback (most recent call last):
  File "/home/alina/my_test_project/make_vocabulary.py", line 28, in read_file
    file = open(file_name, FILE_OPEN_MODE)
IOError: [Errno 2] No such file or directory: 'fileNotExist'
ERROR    [2017-04-06 10:47:33,194] Failed.
Traceback (most recent call last):
  File "/home/alina/my_test_project/make_vocabulary.py", line 28, in read_file
    file = open(file_name, FILE_OPEN_MODE)
IOError: [Errno 2] No such file or directory: 'fileNotExist'
ERROR    [2017-04-06 11:30:19,953] Failed.
Traceback (most recent call last):
  File "/home/alina/my_test_project/make_vocabulary.py", line 13, in take_file_name
    file_name = sys.argv[1]
IndexError: list index out of range
ERROR    [2017-04-06 11:33:48,397] Failed.
Traceback (most recent call last):
  File "/home/alina/my_test_project/make_vocabulary.py", line 24, in read_file
    file = open(file_name, FILE_OPEN_MODE)
IOError: [Errno 2] No such file or directory: 'fileNotExist'
ERROR    [2017-04-06 11:51:33,871] Failed.
Traceback (most recent call last):
  File "/home/alina/my_test_project/make_vocabulary.py", line 23, in read_file
    file = open(file_name, FILE_OPEN_MODE)
IOError: [Errno 2] No such file or directory: 'fileNotExist'
ERROR    [2017-04-06 11:51:33,933] Failed.
Traceback (most recent call last):
  File "/home/alina/my_test_project/make_vocabulary.py", line 23, in read_file
    file = open(file_name, FILE_OPEN_MODE)
IOError: [Errno 2] No such file or directory: '/sct/tests/test_positive/file1.txt'
ERROR    [2017-04-06 11:51:33,956] Failed.
Traceback (most recent call last):
  File "/home/alina/my_test_project/make_vocabulary.py", line 23, in read_file
    file = open(file_name, FILE_OPEN_MODE)
IOError: [Errno 2] No such file or directory: '/sct/tests/test_positive/file1.txt'
ERROR    [2017-04-06 11:53:20,425] Failed.
Traceback (most recent call last):
  File "/home/alina/my_test_project/make_vocabulary.py", line 23, in read_file
    file = open(file_name, FILE_OPEN_MODE)
IOError: [Errno 2] No such file or directory: 'fileNotExist'
ERROR    [2017-04-06 11:58:03,487] Failed.
Traceback (most recent call last):
  File "/home/alina/my_test_project/make_vocabulary.py", line 23, in read_file
    file = open(file_name, FILE_OPEN_MODE)
IOError: [Errno 2] No such file or directory: 'fileNotExist'
ERROR    [2017-04-06 12:00:06,541] Failed.
Traceback (most recent call last):
  File "/home/alina/my_test_project/make_vocabulary.py", line 23, in read_file
    file = open(file_name, FILE_OPEN_MODE)
IOError: [Errno 2] No such file or directory: 'fileNotExist'
ERROR    [2017-04-06 12:00:59,597] Failed.
Traceback (most recent call last):
  File "/home/alina/my_test_project/make_vocabulary.py", line 23, in read_file
    file = open(file_name, FILE_OPEN_MODE)
IOError: [Errno 2] No such file or directory: 'fileNotExist'
ERROR    [2017-04-06 12:01:27,249] Failed.
Traceback (most recent call last):
  File "/home/alina/my_test_project/make_vocabulary.py", line 23, in read_file
    file = open(file_name, FILE_OPEN_MODE)
IOError: [Errno 2] No such file or directory: 'fileNotExist'
ERROR    [2017-04-06 12:02:06,807] Failed.
Traceback (most recent call last):
  File "/home/alina/my_test_project/make_vocabulary.py", line 23, in read_file
    file = open(file_name, FILE_OPEN_MODE)
IOError: [Errno 2] No such file or directory: 'fileNotExist'
ERROR    [2017-04-06 12:02:36,548] Failed.
Traceback (most recent call last):
  File "/home/alina/my_test_project/make_vocabulary.py", line 23, in read_file
    file = open(file_name, FILE_OPEN_MODE)
IOError: [Errno 2] No such file or directory: 'fileNotExist'
ERROR    [2017-04-06 12:03:00,413] Failed.
Traceback (most recent call last):
  File "/home/alina/my_test_project/make_vocabulary.py", line 23, in read_file
    file = open(file_name, FILE_OPEN_MODE)
IOError: [Errno 2] No such file or directory: 'fileNotExist'
ERROR    [2017-04-06 12:04:45,422] Failed.
Traceback (most recent call last):
  File "/home/alina/my_test_project/make_vocabulary.py", line 13, in take_file_name
    file_name = sys.argv[1]
IndexError: list index out of range
ERROR    [2017-04-06 12:05:14,694] Failed.
Traceback (most recent call last):
  File "/home/alina/my_test_project/make_vocabulary.py", line 23, in read_file
    file = open(file_name, FILE_OPEN_MODE)
IOError: [Errno 2] No such file or directory: 'fileNotExist'
ERROR    [2017-04-06 12:06:24,106] Failed.
Traceback (most recent call last):
  File "/home/alina/my_test_project/make_vocabulary.py", line 23, in read_file
    file = open(file_name, FILE_OPEN_MODE)
IOError: [Errno 2] No such file or directory: 'fileNotExist'
ERROR    [2017-04-06 12:08:00,829] Failed.
Traceback (most recent call last):
  File "/home/alina/my_test_project/make_vocabulary.py", line 23, in read_file
    file = open(file_name, FILE_OPEN_MODE)
IOError: [Errno 2] No such file or directory: 'fileNotExist'
ERROR    [2017-04-06 12:11:58,359] Failed.
Traceback (most recent call last):
  File "/home/alina/my_test_project/make_vocabulary.py", line 23, in read_file
    file = open(file_name, FILE_OPEN_MODE)
IOError: [Errno 2] No such file or directory: 'fileNotExist'
ERROR    [2017-04-06 12:28:08,176] Failed.
Traceback (most recent call last):
  File "/home/alina/my_test_project/make_vocabulary.py", line 23, in read_file
    file = open(file_name, FILE_OPEN_MODE)
IOError: [Errno 2] No such file or directory: 'fileNotExist'
ERROR    [2017-04-06 12:32:56,230] Failed.
Traceback (most recent call last):
  File "/home/alina/my_test_project/make_vocabulary.py", line 23, in read_file
    file = open(file_name, FILE_OPEN_MODE)
IOError: [Errno 2] No such file or directory: 'fileNotExist'
ERROR    [2017-04-06 12:34:20,970] Failed.
Traceback (most recent call last):
  File "/home/alina/my_test_project/make_vocabulary.py", line 23, in read_file
    file = open(file_name, FILE_OPEN_MODE)
IOError: [Errno 2] No such file or directory: 'fileNotExist'
ERROR    [2017-04-06 12:45:28,515] Failed.
Traceback (most recent call last):
  File "/home/alina/my_test_project/make_vocabulary.py", line 23, in read_file
    file = open(file_name, FILE_OPEN_MODE)
IOError: [Errno 2] No such file or directory: 'fileNotExist'
ERROR    [2017-04-06 12:46:16,162] Failed.
Traceback (most recent call last):
  File "/home/alina/my_test_project/make_vocabulary.py", line 23, in read_file
    file = open(file_name, FILE_OPEN_MODE)
IOError: [Errno 2] No such file or directory: 'fileNotExist'
ERROR    [2017-04-06 12:47:37,707] Failed.
Traceback (most recent call last):
  File "/home/alina/my_test_project/make_vocabulary.py", line 23, in read_file
    file = open(file_name, FILE_OPEN_MODE)
IOError: [Errno 2] No such file or directory: 'fileNotExist'
ERROR    [2017-04-06 12:48:36,535] Failed.
Traceback (most recent call last):
  File "/home/alina/my_test_project/make_vocabulary.py", line 23, in read_file
    file = open(file_name, FILE_OPEN_MODE)
IOError: [Errno 2] No such file or directory: 'fileNotExist'
ERROR    [2017-04-06 12:49:32,520] Failed.
Traceback (most recent call last):
  File "/home/alina/my_test_project/make_vocabulary.py", line 23, in read_file
    file = open(file_name, FILE_OPEN_MODE)
IOError: [Errno 2] No such file or directory: 'fileNotExist'
ERROR    [2017-04-06 12:50:26,323] Failed.
Traceback (most recent call last):
  File "/home/alina/my_test_project/make_vocabulary.py", line 23, in read_file
    file = open(file_name, FILE_OPEN_MODE)
IOError: [Errno 2] No such file or directory: 'fileNotExist'
ERROR    [2017-04-06 12:51:27,570] Failed.
Traceback (most recent call last):
  File "/home/alina/my_test_project/make_vocabulary.py", line 23, in read_file
    file = open(file_name, FILE_OPEN_MODE)
IOError: [Errno 2] No such file or directory: 'fileNotExist'
ERROR    [2017-04-06 12:52:06,427] Failed.
Traceback (most recent call last):
  File "/home/alina/my_test_project/make_vocabulary.py", line 23, in read_file
    file = open(file_name, FILE_OPEN_MODE)
IOError: [Errno 2] No such file or directory: 'fileNotExist'
ERROR    [2017-04-06 12:53:29,016] Failed.
Traceback (most recent call last):
  File "/home/alina/my_test_project/make_vocabulary.py", line 23, in read_file
    file = open(file_name, FILE_OPEN_MODE)
IOError: [Errno 2] No such file or directory: 'fileNotExist'
ERROR    [2017-04-06 12:55:55,348] Failed.
Traceback (most recent call last):
  File "/home/alina/my_test_project/make_vocabulary.py", line 23, in read_file
    file = open(file_name, FILE_OPEN_MODE)
IOError: [Errno 2] No such file or directory: 'fileNotExist'
ERROR    [2017-04-06 12:56:03,771] Failed.
Traceback (most recent call last):
  File "/home/alina/my_test_project/make_vocabulary.py", line 23, in read_file
    file = open(file_name, FILE_OPEN_MODE)
IOError: [Errno 2] No such file or directory: 'fileNotExist'
ERROR    [2017-04-06 13:00:05,382] Failed.
Traceback (most recent call last):
  File "/home/alina/my_test_project/make_vocabulary.py", line 23, in read_file
    file = open(file_name, FILE_OPEN_MODE)
IOError: [Errno 2] No such file or directory: 'fileNotExist'
ERROR    [2017-04-06 13:02:13,214] Failed.
Traceback (most recent call last):
  File "/home/alina/my_test_project/make_vocabulary.py", line 23, in read_file
    file = open(file_name, FILE_OPEN_MODE)
IOError: [Errno 2] No such file or directory: 'fileNotExist'
ERROR    [2017-04-06 13:03:47,003] Failed.
Traceback (most recent call last):
  File "/home/alina/my_test_project/make_vocabulary.py", line 23, in read_file
    file = open(file_name, FILE_OPEN_MODE)
IOError: [Errno 2] No such file or directory: 'fileNotExist'
ERROR    [2017-04-06 13:04:06,635] Failed.
Traceback (most recent call last):
  File "/home/alina/my_test_project/make_vocabulary.py", line 23, in read_file
    file = open(file_name, FILE_OPEN_MODE)
IOError: [Errno 2] No such file or directory: 'fileNotExist'
ERROR    [2017-04-06 13:04:22,083] Failed.
Traceback (most recent call last):
  File "/home/alina/my_test_project/make_vocabulary.py", line 23, in read_file
    file = open(file_name, FILE_OPEN_MODE)
IOError: [Errno 2] No such file or directory: 'fileNotExist'
